<?xml version='1.0' encoding='utf-8'?>
<mujoco model="kuavo scene">
  <include file="biped_s45.xml" />
  <include file="../../assets/shampoo/model1.xml" />
  <include file="../../assets/shampoo/model2.xml" />
  <include file="../../assets/shampoo/model3.xml" />
  
  
  <statistic center="0 0 1" extent="1.8" />
  <visual>
    <headlight diffuse="0.2220980094 0.2424697796 0.7103672873" ambient="0.1956832948 0.4586231268 0.250338978" specular="0.1803252927 0.3781660051 0.09352643705" />
    <rgba haze="0.15 0.25 0.35 1" />
    <global azimuth="160" elevation="-20" />
  </visual>

  <asset>

    <texture file="../../assets/textures/wall3.png" type="2d" name="wall" />
    <material name="walls_mat" reflectance="0.1" shininess="0.1" texture="wall" texuniform="true" />

    <texture file="../../assets/textures/roof1.png" type="2d" name="roof" />
    <material name="roofs_mat" reflectance="0.1" shininess="0.1" texture="roof" texuniform="true" />

    
    <texture name="ground_tex" type="2d" file="../../assets/textures/ground2.png" />
    <material name="ground_mat" texture="ground_tex" texuniform="true" reflectance="0" /> 

    <texture name="tex-ceramic" type="cube" file="../../assets/textures/green.png" />
    <material name="table_ceramic" texture="tex-ceramic" specular="0.20" shininess="0" reflectance="0" />

    <texture name="tex-steel-brushed" type="cube" file="../../assets/textures/steel-brushed.png" />
    <material name="table_legs_metal" texture="tex-steel-brushed" specular="0.0" shininess="0.8" reflectance="0.8" />
  </asset>

  <worldbody>
    <light pos="1 0 3.5" dir="-0.2 0 -1" directional="false" />
    <geom name="floor" size="0 0 0.05" type="plane" material="ground_mat" />

    <geom name="wall_front" type="box" size="10 5 2" pos="0 10 2.5" euler="-1.57079633 0 3.14159265" material="walls_mat" contype="0" conaffinity="0" />

    <geom name="wall_back" type="box" size="10 5 2" pos="0 -10 2.5" euler="-1.57079633 0 0" material="walls_mat" contype="0" conaffinity="0" />

    <geom name="wall_right" type="box" size="10 5 2" pos="10 0 2.5" euler="0 1.57079633 1.57" material="walls_mat" contype="0" conaffinity="0" />

    <geom name="wall_left" type="box" size="10 5 2" pos="-10 0 2.5" euler="0 -1.57079633 1.57" material="walls_mat" contype="0" conaffinity="0" />

    <geom name="roof" type="plane" size="10 10 5" pos="0 0 5" euler="3.14159265 0 0" material="roofs_mat" />


    <body name="marker1" pos="0.32 0.4 0.671">
      <geom name="marker1" type="box" size="0.18 0.18 0.001" rgba="0.4227102301 0.7225401853 0.5675298039 1" contype="0" conaffinity="0" />
    </body>

    <body name="table" pos="0.5 0 0.65">
      
      <geom name="table_top" type="box" size="0.40 0.8 0.02" friction="1 0.005 0.0001" rgba="0.09840815826 0.3663330944 0.4971438558 1" />

      
      

      
      
      <geom name="leg_fl" type="cylinder" size="0.03 0.4" pos="0.2  0.6 -0.4" material="table_legs_metal" contype="0" conaffinity="0" />
      <geom name="leg_fr" type="cylinder" size="0.03 0.4" pos=" 0.2 -0.6 -0.4" material="table_legs_metal" contype="0" conaffinity="0" />
      <geom name="leg_rl" type="cylinder" size="0.03 0.4" pos="-0.2  0.6 -0.4" material="table_legs_metal" contype="0" conaffinity="0" />
      <geom name="leg_rr" type="cylinder" size="0.03 0.4" pos="-0.2 -0.6 -0.4" material="table_legs_metal" contype="0" conaffinity="0" />
    </body>


      <body name="belt_plate1" pos="0.6 0 5.8">  
            <inertial pos="0 0 0" mass="1e-1" diaginertia="1e-6 1e-6 1e-6" />
            <joint name="belt_slide" type="slide" axis="0 1 0" range="-20 20" damping="0.001" />
            <geom name="belt_geom1" type="box" size="0.4 100 0.01" material="roofs_mat" friction="1.0 0.005 0.0001" />
      </body>
  </worldbody>
  <actuator>
    <velocity name="belt_speed" joint="belt_slide" kv="1" ctrlrange="-0.1 0.1" />
  </actuator>



  

</mujoco>