<?xml version='1.0' encoding='utf-8'?>
<mujoco model="kuavo scene">
  <include file="biped_s45.xml" />
  <statistic center="0 0 1" extent="1.8" />
  <visual>
    <headlight diffuse="0.2652139007 0.2515352102 0.4792580412" ambient="0.0875257662 0.1017262921 0.1013253542" specular="0.16832445 0.05438302646 0.129611373" />
    <rgba haze="0.15 0.25 0.35 1" />
    <global azimuth="160" elevation="-20" />
  </visual>

  <asset>

    <texture file="../../assets/textures/wall3.png" type="2d" name="wall" />
    <material name="walls_mat" reflectance="0.1" shininess="0.1" texture="wall" texuniform="true" />

    <texture file="../../assets/textures/roof1.png" type="2d" name="roof" />
    <material name="roofs_mat" reflectance="0.1" shininess="0.1" texture="roof" texuniform="true" />

    <texture file="../../assets/textures/green.png" type="2d" name="belt" />
    <material name="belt_mat" texture="belt" texuniform="true" />

    <texture file="../../assets/textures/metal.png" type="2d" name="metal" />
    <material name="metal_mat" texture="metal" texuniform="true" />

    
    <texture name="ground_tex" type="2d" file="../../assets/textures/ground2.png" />
    <material name="ground_mat" texture="ground_tex" texuniform="true" reflectance="0" /> 

    <texture name="tex-ceramic" type="cube" file="../../assets/textures/green.png" />
    <material name="table_ceramic" texture="tex-ceramic" specular="0.20" shininess="0" reflectance="0" />

    <texture name="tex-steel-brushed" type="cube" file="../../assets/textures/steel-brushed.png" />
    <material name="table_legs_metal" texture="tex-steel-brushed" specular="0.0" shininess="0.8" reflectance="0.8" />
  </asset>

  <worldbody>
    <light pos="1 0 3.5" dir="-0.3 0 -1" directional="false" />
    <geom name="floor" size="0 0 0.05" type="plane" material="ground_mat" />

    <geom name="wall_front" type="box" size="10 5 2" pos="0 10 2.5" euler="-1.57079633 0 3.14159265" material="walls_mat" contype="0" conaffinity="0" />

    <geom name="wall_back" type="box" size="10 5 2" pos="0 -10 2.5" euler="-1.57079633 0 0" material="walls_mat" contype="0" conaffinity="0" />

    <geom name="wall_right" type="box" size="10 5 2" pos="10 0 2.5" euler="0 1.57079633 1.57" material="walls_mat" contype="0" conaffinity="0" />

    <geom name="wall_left" type="box" size="10 5 2" pos="-10 0 2.5" euler="0 -1.57079633 1.57" material="walls_mat" contype="0" conaffinity="0" />

    <geom name="roof" type="plane" size="10 10 5" pos="0 0 5" euler="3.14159265 0 0" material="roofs_mat" />



    <body name="belt_plate1" pos="0.6 0 0.8">  
      <inertial pos="0 0 0" mass="1e-1" diaginertia="1e-6 1e-6 1e-6" />
      <joint name="belt_slide" type="slide" axis="0 1 0" range="-20 20" damping="0.001" />
      <geom name="belt_geom1" type="box" size="0.4 100 0.01" material="belt_mat" friction="1.0 0.005 0.0001" />
    </body>

    <body name="box_grab" pos="0.55 -0.3 0.95">
      <freejoint name="box_grab" />
      <geom name="box_on_belt" type="cylinder" size="0.025 0.08" mass="1e-2" friction="1.5 0.005 0.0001" rgba="0.2180493456 0.5116004017 0.8503102698 1" pos="0 0 0" />

      <geom name="box_base_disk" type="box" size="0.06 0.06 0.01" mass="1e-2" friction="1 0.005 0.0001" rgba="0.2171044948 0.073318425 0.06350515136 1" pos="0 0 -0.081" />
    </body>



    <body name="marker1" pos="0.4322236743 0.06978371951 0.89">
      <geom type="box" size="0.07 0.07 0.02" rgba="0.7115468423 0.3022500559 0.9383252748 1" />
    </body>

    <body name="marker2" pos="0.4523970014 0.4880975559 0.871">
      <geom type="box" size="0.035 0.035 0.001" rgba="0.9660871462 0.8736083929 0.1075195632 1" contype="0" conaffinity="0" />
    </body>



    <body name="table" pos="0.6 0.75 0.85">
      
      <geom name="table_top" type="box" size="0.40 0.8 0.02" material="table_ceramic" friction="2 0.005 0.0001" />
      
      <geom name="leg_fl" type="cylinder" size="0.03 0.4" pos="0.2  0.6 -0.4" material="table_legs_metal" contype="0" conaffinity="0" />
      <geom name="leg_fr" type="cylinder" size="0.03 0.4" pos=" 0.2 -0.6 -0.4" material="table_legs_metal" contype="0" conaffinity="0" />
      <geom name="leg_rl" type="cylinder" size="0.03 0.4" pos="-0.2  0.6 -0.4" material="table_legs_metal" contype="0" conaffinity="0" />
      <geom name="leg_rr" type="cylinder" size="0.03 0.4" pos="-0.2 -0.6 -0.4" material="table_legs_metal" contype="0" conaffinity="0" />
    </body>
  </worldbody>

  <actuator>
    <velocity name="belt_speed" joint="belt_slide" kv="1" ctrlrange="-0.1 0.1" />
  </actuator>




  

</mujoco>